<?xml version="1.0" encoding="UTF-8"?>
<!-- Generated by org.testng.reporters.JUnitReportReporter -->
<testsuite hostname="M430DTRV" name="dataDrivenTesting.Get_Data_Driven" tests="3" failures="1" timestamp="9 Feb 2021 12:58:34 GMT" time="4.848" errors="0">
  <testcase name="getemployee" time="1.072" classname="dataDrivenTesting.Get_Data_Driven">
    <failure type="junit.framework.AssertionFailedError" message="expected:&lt;200&gt; but was:&lt;429&gt;">
      <![CDATA[junit.framework.AssertionFailedError: expected:<200> but was:<429>
	at junit.framework.Assert.fail(Assert.java:50)
	at junit.framework.Assert.failNotEquals(Assert.java:287)
	at junit.framework.Assert.assertEquals(Assert.java:67)
	at junit.framework.Assert.assertEquals(Assert.java:199)
	at junit.framework.Assert.assertEquals(Assert.java:205)
	at dataDrivenTesting.Get_Data_Driven.getemployee(Get_Data_Driven.java:39)
	at sun.reflect.NativeMethodAccessorImpl.invoke0(Native Method)
	at sun.reflect.NativeMethodAccessorImpl.invoke(Unknown Source)
	at sun.reflect.DelegatingMethodAccessorImpl.invoke(Unknown Source)
	at java.lang.reflect.Method.invoke(Unknown Source)
	at org.testng.internal.MethodInvocationHelper.invokeMethod(MethodInvocationHelper.java:85)
	at org.testng.internal.Invoker.invokeMethod(Invoker.java:639)
	at org.testng.internal.Invoker.invokeTestMethod(Invoker.java:816)
	at org.testng.internal.Invoker.invokeTestMethods(Invoker.java:1124)
	at org.testng.internal.TestMethodWorker.invokeTestMethods(TestMethodWorker.java:125)
	at org.testng.internal.TestMethodWorker.run(TestMethodWorker.java:108)
	at org.testng.TestRunner.privateRun(TestRunner.java:774)
	at org.testng.TestRunner.run(TestRunner.java:624)
	at org.testng.SuiteRunner.runTest(SuiteRunner.java:359)
	at org.testng.SuiteRunner.runSequentially(SuiteRunner.java:354)
	at org.testng.SuiteRunner.privateRun(SuiteRunner.java:312)
	at org.testng.SuiteRunner.run(SuiteRunner.java:261)
	at org.testng.SuiteRunnerWorker.runSuite(SuiteRunnerWorker.java:52)
	at org.testng.SuiteRunnerWorker.run(SuiteRunnerWorker.java:86)
	at org.testng.TestNG.runSuitesSequentially(TestNG.java:1215)
	at org.testng.TestNG.runSuitesLocally(TestNG.java:1140)
	at org.testng.TestNG.run(TestNG.java:1048)
	at org.testng.remote.AbstractRemoteTestNG.run(AbstractRemoteTestNG.java:132)
	at org.testng.remote.RemoteTestNG.initAndRun(RemoteTestNG.java:230)
	at org.testng.remote.RemoteTestNG.main(RemoteTestNG.java:76)
]]>
    </failure>
  </testcase> <!-- getemployee -->
  <testcase name="getemployee" time="2.697" classname="dataDrivenTesting.Get_Data_Driven"/>
  <testcase name="getemployee" time="1.079" classname="dataDrivenTesting.Get_Data_Driven"/>
</testsuite> <!-- dataDrivenTesting.Get_Data_Driven -->
